Workbook

Sheet LOG
A3: Date | B3: Name | C3: Sheet Name | D3: Cells | E3: Comments
A4: 43529 | B4: Mikkel Bosack Simonsen | C4: TTB from TIMES population | D4: =ADDRESS(ROW('TTB from TIMES population'!B3),COLUMN('TTB from TIMES population'!B3),4,1) -> B3 | E4: Updated Population projections according to statistics denmark
A5: 43437 | B5: Mikkel Bosack Simonsen | C5: Explanation (2) | D5: =ADDRESS(ROW('Explanation (2)'!B3),COLUMN('Explanation (2)'!B3),4,1) -> B3 | E5: Combining of all TTB needed files.

Sheet TTB constraint
D2: DEMAND calculated travel time budget
B3: ~TFM_INS | P3: ~TFM_INS
B4: Attribute | C4: Year | D4: DKE | E4: DKW | F4: Pset_PN | P4: Attribute | Q4: Year | R4: DKE | S4: DKW | T4: Pset_PN
B5: ACT_BND | C5: 2010 | D5: =Speed!AC55 -> 642.09525 | E5: =Speed!AD55 -> 747.77618 | F5: MINTTB | H5: =D5+E5 -> 1389.8714 | P5: COST | Q5: 2010 | R5: 1e-05 | S5: 1e-05 | T5: MINTTB
B6: ACT_BND | C6: 2020 | D6: =Speed!AF55 -> 756.57385 | E6: =Speed!AG55 -> 890.40879 | F6: MINTTB | H6: =D6+E6 -> 1646.9826 | J6: =H6/$H$5 -> 1.1849892
B7: ACT_BND | C7: 2030 | D7: =Speed!AI55 -> 788.17232 | E7: =Speed!AJ55 -> 926.64671 | F7: MINTTB | H7: =D7+E7 -> 1714.819 | J7: =H7/$H$5 -> 1.2337969
B8: ACT_BND | C8: 2040 | D8: =Speed!AL55 -> 820.80477 | E8: =Speed!AM55 -> 977.19286 | F8: MINTTB | H8: =D8+E8 -> 1797.9976 | J8: =H8/$H$5 -> 1.2936431
B9: ACT_BND | C9: 2050 | D9: =Speed!AO55 -> 852.9856 | E9: =Speed!AP55 -> 1024.1405 | F9: MINTTB | H9: =D9+E9 -> 1877.1261 | J9: =H9/$H$5 -> 1.3505753
B10: ACT_BND | C10: 0 | D10: 5 | E10: 5 | F10: MINTTB
H11: =H9/H5 -> 1.3505753
D15: POPULATION calculated travel time budget
B17: Attribute | C17: Year | D17: DKE | E17: DKW | F17: Pset_PN
B18: ACT_BND | C18: 2010 | D18: ='TTB from TIMES population'!R8 -> 642.0953 | E18: ='TTB from TIMES population'!S8 -> 747.7762 | F18: MINTTB | H18: =D18+E18 -> 1389.8715
B19: ACT_BND | C19: 2020 | D19: ='TTB from TIMES population'!R9 -> 680.86949 | E19: ='TTB from TIMES population'!S9 -> 786.81925 | F19: MINTTB | H19: =D19+E19 -> 1467.6887
B20: ACT_BND | C20: 2030 | D20: ='TTB from TIMES population'!R10 -> 721.96948 | E20: ='TTB from TIMES population'!S10 -> 812.18032 | F20: MINTTB | H20: =D20+E20 -> 1534.1498
B21: ACT_BND | C21: 2040 | D21: ='TTB from TIMES population'!R11 -> 750.5731 | E21: ='TTB from TIMES population'!S11 -> 830.62958 | F21: MINTTB | H21: =D21+E21 -> 1581.2027
B22: ACT_BND | C22: 2050 | D22: ='TTB from TIMES population'!R12 -> 761.20889 | E22: ='TTB from TIMES population'!S12 -> 836.86951 | F22: MINTTB | H22: =D22+E22 -> 1598.0784
B23: ACT_BND | C23: 0 | D23: ='TTB from TIMES population'!R13 -> 5 | E23: ='TTB from TIMES population'!S13 -> 5 | F23: MINTTB
H24: =H22/H18 -> 1.149803

Sheet Sheet1
B2: Year | C2: 2007 | D2: 2008 | E2: 2009 | F2: 2010 | G2: 2011 | H2: 2012 | I2: 2013 | J2: 2014 | K2: Average | N2: TU Average travel time [h] | P2: =K3/60 -> 0.92558333 | S2: Data on population projections from statistics denmark
B3: Travel Time [mnts] | C3: 57.32 | D3: 55.48 | E3: 56.63 | F3: 54.75 | G3: 56.42 | H3: 56.71 | I3: 53.08 | J3: 53.89 | K3: =AVERAGE(C3:J3) -> 55.535 | N3: TU Schafer | P3: 1.1 | S3: http://www.statistikbanken.dk/statbank5a/default.asp?w=1920
N4: Days per year | P4: 365 | AD4: Adjsted Travel time budget according to new population growth and previos calculation e.g. travel time budget is calculated on the adult populations transport habbits
B6: Population projection | H6: Travel time budget with 0.93[Mhs] | S6: Population projection | AE6: Population projection | AK6: Travel time budget with 0.93[Mhs]
C7: DKE | D7: DKW | E7: Total | I7: DKE | J7: DKW | K7: Total | T7: DKE | U7: DKW | V7: Total | Z7: Difference bestween TU and DS population (w/wo Kids) | AA7: Variation in procentral increase | AF7: DKE | AG7: DKW | AH7: Total | AL7: DKE | AM7: DKW | AN7: Total
B8: 2010 | C8: 2155666 | D8: 2613168 | E8: 4768834 | H8: 2010 | I8: =C8*$P$2*$P$4/10^6 -> 728.26571 | J8: =D8*$P$2*$P$4/10^6 -> 882.82723 | K8: =E8*$P$2*$P$4/10^6 -> 1611.0929 | S8: 2010 | T8: =V8*$C$15/$E$15 -> 2543633 | U8: =V8*$D$15/$E$15 -> 2991367 | V8: 5535000 | Y8: 2010 | Z8: =V8/E8 -> 1.1606611 | AA8: =Z8/$Z$8 -> 1 | AE8: 2010 | AF8: =C8*$AA8 -> 2155666 | AG8: =D8*$AA8 -> 2613168 | AH8: =E8*$AA8 -> 4768834 | AK8: 2010 | AL8: =AF8*$P$2*$P$4/10^6 -> 728.26571 | AM8: =AG8*$P$2*$P$4/10^6 -> 882.82723 | AN8: =AH8*$P$2*$P$4/10^6 -> 1611.0929
B9: 2011 | C9: 2173141 | D9: 2622809 | E9: 4795950 | H9: 2011 | I9: =C9*$P$2*$P$4/10^6 -> 734.16943 | J9: =D9*$P$2*$P$4/10^6 -> 886.08433 | K9: =E9*$P$2*$P$4/10^6 -> 1620.2538 | S9: 2011 | T9: =V9*$C$15/$E$15 -> 2555581.5 | U9: =V9*$D$15/$E$15 -> 3005418.5 | V9: 5561000 | Y9: 2011 | Z9: =V9/E9 -> 1.15952 | AA9: =Z9/$Z$8 -> 0.99901688 | AE9: 2011 | AF9: =C9*$AA9 -> 2171004.6 | AG9: =D9*$AA9 -> 2620230.5 | AH9: =E9*$AA9 -> 4791235 | AK9: 2011 | AL9: =AF9*$P$2*$P$4/10^6 -> 733.44765 | AM9: =AG9*$P$2*$P$4/10^6 -> 885.21321 | AN9: =AH9*$P$2*$P$4/10^6 -> 1618.6609
B10: 2012 | C10: 2187526 | D10: 2632198 | E10: 4819724 | H10: 2012 | I10: =C10*$P$2*$P$4/10^6 -> 739.02923 | J10: =D10*$P$2*$P$4/10^6 -> 889.25629 | K10: =E10*$P$2*$P$4/10^6 -> 1628.2855 | S10: 2012 | T10: =V10*$C$15/$E$15 -> 2564772.5 | U10: =V10*$D$15/$E$15 -> 3016227.5 | V10: 5581000 | Y10: 2012 | Z10: =V10/E10 -> 1.1579501 | AA10: =Z10/$Z$8 -> 0.9976643 | AE10: 2012 | AF10: =C10*$AA10 -> 2182416.6 | AG10: =D10*$AA10 -> 2626050 | AH10: =E10*$AA10 -> 4808466.6 | AK10: 2012 | AL10: =AF10*$P$2*$P$4/10^6 -> 737.30308 | AM10: =AG10*$P$2*$P$4/10^6 -> 887.17926 | AN10: =AH10*$P$2*$P$4/10^6 -> 1624.4823
B11: 2013 | C11: 2204115 | D11: 2641524 | E11: 4845639 | H11: 2013 | I11: =C11*$P$2*$P$4/10^6 -> 744.63362 | J11: =D11*$P$2*$P$4/10^6 -> 892.40696 | K11: =E11*$P$2*$P$4/10^6 -> 1637.0406 | S11: 2013 | T11: =V11*$C$15/$E$15 -> 2574882.7 | U11: =V11*$D$15/$E$15 -> 3028117.3 | V11: 5603000 | Y11: 2013 | Z11: =V11/E11 -> 1.1562974 | AA11: =Z11/$Z$8 -> 0.99624039 | AE11: 2013 | AF11: =C11*$AA11 -> 2195828.4 | AG11: =D11*$AA11 -> 2631592.9 | AH11: =E11*$AA11 -> 4827421.3 | AK11: 2013 | AL11: =AF11*$P$2*$P$4/10^6 -> 741.83409 | AM11: =AG11*$P$2*$P$4/10^6 -> 889.05187 | AN11: =AH11*$P$2*$P$4/10^6 -> 1630.886
B12: 2014 | C12: 2223737 | D12: 2652705 | E12: 4876442 | H12: 2014 | I12: =C12*$P$2*$P$4/10^6 -> 751.26268 | J12: =D12*$P$2*$P$4/10^6 -> 896.18433 | K12: =E12*$P$2*$P$4/10^6 -> 1647.447 | S12: 2014 | T12: =V12*$C$15/$E$15 -> 2574882.7 | U12: =V12*$D$15/$E$15 -> 3028117.3 | V12: 5603000 | Y12: 2014 | Z12: =V12/E12 -> 1.1489935 | AA12: =Z12/$Z$8 -> 0.98994745 | AE12: 2014 | AF12: =C12*$AA12 -> 2201382.8 | AG12: =D12*$AA12 -> 2626038.5 | AH12: =E12*$AA12 -> 4827421.3 | AK12: 2014 | AL12: =AF12*$P$2*$P$4/10^6 -> 743.71057 | AM12: =AG12*$P$2*$P$4/10^6 -> 887.17539 | AN12: =AH12*$P$2*$P$4/10^6 -> 1630.886
B13: 2015 | C13: 2246638 | D13: 2666283 | E13: 4912921 | H13: 2015 | I13: =C13*$P$2*$P$4/10^6 -> 758.9995 | J13: =D13*$P$2*$P$4/10^6 -> 900.77149 | K13: =E13*$P$2*$P$4/10^6 -> 1659.771 | S13: 2015 | T13: =V13*$C$15/$E$15 -> 2585912 | U13: =V13*$D$15/$E$15 -> 3041088 | V13: 5627000 | Y13: 2015 | Z13: =V13/E13 -> 1.1453471 | AA13: =Z13/$Z$8 -> 0.98680585 | AE13: 2015 | AF13: =C13*$AA13 -> 2216995.5 | AG13: =D13*$AA13 -> 2631103.7 | AH13: =E13*$AA13 -> 4848099.2 | AK13: 2015 | AL13: =AF13*$P$2*$P$4/10^6 -> 748.98515 | AM13: =AG13*$P$2*$P$4/10^6 -> 888.88658 | AN13: =AH13*$P$2*$P$4/10^6 -> 1637.8717
B14: 2016 | C14: 2267174 | D14: 2678232 | E14: 4945406 | H14: 2016 | I14: =C14*$P$2*$P$4/10^6 -> 765.93734 | J14: =D14*$P$2*$P$4/10^6 -> 904.80832 | K14: =E14*$P$2*$P$4/10^6 -> 1670.7457 | S14: 2016 | T14: =V14*$C$15/$E$15 -> 2622676.4 | U14: =V14*$D$15/$E$15 -> 3084323.6 | V14: 5707000 | Y14: 2016 | Z14: =V14/E14 -> 1.1540003 | AA14: =Z14/$Z$8 -> 0.99426122 | AE14: 2016 | AF14: =C14*$AA14 -> 2254163.2 | AG14: =D14*$AA14 -> 2662862.2 | AH14: =E14*$AA14 -> 4917025.4 | AK14: 2016 | AL14: =AF14*$P$2*$P$4/10^6 -> 761.5418 | AM14: =AG14*$P$2*$P$4/10^6 -> 899.61582 | AN14: =AH14*$P$2*$P$4/10^6 -> 1661.1576
B15: 2017 | C15: 2286733 | D15: 2689247 | E15: 4975980 | H15: 2017 | I15: =C15*$P$2*$P$4/10^6 -> 772.54511 | J15: =D15*$P$2*$P$4/10^6 -> 908.5296 | K15: =E15*$P$2*$P$4/10^6 -> 1681.0747 | S15: 2017 | T15: =V15*$C$15/$E$15 -> 2641977.7 | U15: =V15*$D$15/$E$15 -> 3107022.3 | V15: 5749000 | Y15: 2017 | Z15: =V15/E15 -> 1.1553503 | AA15: =Z15/$Z$8 -> 0.99542436 | AE15: 2017 | AF15: =C15*$AA15 -> 2276269.7 | AG15: =D15*$AA15 -> 2676942 | AH15: =E15*$AA15 -> 4953211.7 | AK15: 2017 | AL15: =AF15*$P$2*$P$4/10^6 -> 769.01022 | AM15: =AG15*$P$2*$P$4/10^6 -> 904.3725 | AN15: =AH15*$P$2*$P$4/10^6 -> 1673.3827
B16: 2018 | C16: 2304325 | D16: 2698716 | E16: 5003041 | H16: 2018 | I16: =C16*$P$2*$P$4/10^6 -> 778.48836 | J16: =D16*$P$2*$P$4/10^6 -> 911.72859 | K16: =E16*$P$2*$P$4/10^6 -> 1690.2169 | S16: 2018 | T16: 2657600 | U16: 3123507 | V16: =SUM(T16:U16) -> 5781107 | Y16: 2018 | Z16: =V16/E16 -> 1.1555186 | AA16: =Z16/$Z$8 -> 0.99556937 | AE16: 2018 | AF16: =C16*$AA16 -> 2294115.4 | AG16: =D16*$AA16 -> 2686759 | AH16: =E16*$AA16 -> 4980874.4 | AK16: 2018 | AL16: =AF16*$P$2*$P$4/10^6 -> 775.03916 | AM16: =AG16*$P$2*$P$4/10^6 -> 907.68906 | AN16: =AH16*$P$2*$P$4/10^6 -> 1682.7282
B17: 2019 | C17: 2320670 | D17: 2708097 | E17: 5028767 | H17: 2019 | I17: =C17*$P$2*$P$4/10^6 -> 784.01032 | J17: =D17*$P$2*$P$4/10^6 -> 914.89785 | K17: =E17*$P$2*$P$4/10^6 -> 1698.9082 | S17: 2019 | T17: 2678707 | U17: 3135513 | V17: =SUM(T17:U17) -> 5814220 | Y17: 2019 | Z17: =V17/E17 -> 1.156192 | AA17: =Z17/$Z$8 -> 0.99614951 | AE17: 2019 | AF17: =C17*$AA17 -> 2311734.3 | AG17: =D17*$AA17 -> 2697669.5 | AH17: =E17*$AA17 -> 5009403.8 | AK17: 2019 | AL17: =AF17*$P$2*$P$4/10^6 -> 780.9915 | AM17: =AG17*$P$2*$P$4/10^6 -> 911.37505 | AN17: =AH17*$P$2*$P$4/10^6 -> 1692.3665
B18: 2020 | C18: 2334482 | D18: 2715050 | E18: 5049532 | H18: 2020 | I18: =C18*$P$2*$P$4/10^6 -> 788.67654 | J18: =D18*$P$2*$P$4/10^6 -> 917.24684 | K18: =E18*$P$2*$P$4/10^6 -> 1705.9234 | S18: 2020 | T18: 2698116 | U18: 3146679 | V18: =SUM(T18:U18) -> 5844795 | Y18: 2020 | Z18: =V18/E18 -> 1.1574924 | AA18: =Z18/$Z$8 -> 0.99726995 | AE18: 2020 | AF18: =C18*$AA18 -> 2328108.8 | AG18: =D18*$AA18 -> 2707637.8 | AH18: =E18*$AA18 -> 5035746.5 | AK18: 2020 | AL18: =AF18*$P$2*$P$4/10^6 -> 786.52341 | AM18: =AG18*$P$2*$P$4/10^6 -> 914.74271 | AN18: =AH18*$P$2*$P$4/10^6 -> 1701.2661
B19: 2021 | C19: 2347523 | D19: 2721385 | E19: 5068908 | H19: 2021 | I19: =C19*$P$2*$P$4/10^6 -> 793.08228 | J19: =D19*$P$2*$P$4/10^6 -> 919.38704 | K19: =E19*$P$2*$P$4/10^6 -> 1712.4693 | S19: 2021 | T19: 2716720 | U19: 3156661 | V19: =SUM(T19:U19) -> 5873381 | Y19: 2021 | Z19: =V19/E19 -> 1.1587074 | AA19: =Z19/$Z$8 -> 0.99831672 | AE19: 2021 | AF19: =C19*$AA19 -> 2343571.5 | AG19: =D19*$AA19 -> 2716804.1 | AH19: =E19*$AA19 -> 5060375.6 | AK19: 2021 | AL19: =AF19*$P$2*$P$4/10^6 -> 791.7473 | AM19: =AG19*$P$2*$P$4/10^6 -> 917.83945 | AN19: =AH19*$P$2*$P$4/10^6 -> 1709.5868
B20: 2022 | C20: 2356963 | D20: 2724709 | E20: 5081672 | H20: 2022 | I20: =C20*$P$2*$P$4/10^6 -> 796.27147 | J20: =D20*$P$2*$P$4/10^6 -> 920.51001 | K20: =E20*$P$2*$P$4/10^6 -> 1716.7815 | S20: 2022 | T20: 2734303 | U20: 3166511 | V20: =SUM(T20:U20) -> 5900814 | Y20: 2022 | Z20: =V20/E20 -> 1.1611954 | AA20: =Z20/$Z$8 -> 1.0004603 | AE20: 2022 | AF20: =C20*$AA20 -> 2358048 | AG20: =D20*$AA20 -> 2725963.3 | AH20: =E20*$AA20 -> 5084011.3 | AK20: 2022 | AL20: =AF20*$P$2*$P$4/10^6 -> 796.63802 | AM20: =AG20*$P$2*$P$4/10^6 -> 920.93376 | AN20: =AH20*$P$2*$P$4/10^6 -> 1717.5718
B21: 2023 | C21: 2364762 | D21: 2726636 | E21: 5091398 | H21: 2023 | I21: =C21*$P$2*$P$4/10^6 -> 798.90627 | J21: =D21*$P$2*$P$4/10^6 -> 921.16103 | K21: =E21*$P$2*$P$4/10^6 -> 1720.0673 | S21: 2023 | T21: 2751292 | U21: 3176484 | V21: =SUM(T21:U21) -> 5927776 | Y21: 2023 | Z21: =V21/E21 -> 1.1642728 | AA21: =Z21/$Z$8 -> 1.0031117 | AE21: 2023 | AF21: =C21*$AA21 -> 2372120.5 | AG21: =D21*$AA21 -> 2735120.6 | AH21: =E21*$AA21 -> 5107241.1 | AK21: 2023 | AL21: =AF21*$P$2*$P$4/10^6 -> 801.39226 | AM21: =AG21*$P$2*$P$4/10^6 -> 924.02745 | AN21: =AH21*$P$2*$P$4/10^6 -> 1725.4197
B22: 2024 | C22: 2370504 | D22: 2726993 | E22: 5097497 | H22: 2024 | I22: =C22*$P$2*$P$4/10^6 -> 800.84613 | J22: =D22*$P$2*$P$4/10^6 -> 921.28163 | K22: =E22*$P$2*$P$4/10^6 -> 1722.1278 | S22: 2024 | T22: 2767951 | U22: 3186720 | V22: =SUM(T22:U22) -> 5954671 | Y22: 2024 | Z22: =V22/E22 -> 1.1681559 | AA22: =Z22/$Z$8 -> 1.0064573 | AE22: 2024 | AF22: =C22*$AA22 -> 2385811.2 | AG22: =D22*$AA22 -> 2744602.1 | AH22: =E22*$AA22 -> 5130413.3 | AK22: 2024 | AL22: =AF22*$P$2*$P$4/10^6 -> 806.01747 | AM22: =AG22*$P$2*$P$4/10^6 -> 927.23066 | AN22: =AH22*$P$2*$P$4/10^6 -> 1733.2481
B23: 2025 | C23: 2376092 | D23: 2727475 | E23: 5103567 | H23: 2025 | I23: =C23*$P$2*$P$4/10^6 -> 802.73397 | J23: =D23*$P$2*$P$4/10^6 -> 921.44447 | K23: =E23*$P$2*$P$4/10^6 -> 1724.1784 | S23: 2025 | T23: 2784425 | U23: 3197217 | V23: =SUM(T23:U23) -> 5981642 | Y23: 2025 | Z23: =V23/E23 -> 1.1720512 | AA23: =Z23/$Z$8 -> 1.0098135 | AE23: 2025 | AF23: =C23*$AA23 -> 2399409.8 | AG23: =D23*$AA23 -> 2754241.1 | AH23: =E23*$AA23 -> 5153650.9 | AK23: 2025 | AL23: =AF23*$P$2*$P$4/10^6 -> 810.61161 | AM23: =AG23*$P$2*$P$4/10^6 -> 930.48708 | AN23: =AH23*$P$2*$P$4/10^6 -> 1741.0987
B24: 2026 | C24: 2380668 | D24: 2727694 | E24: 5108362 | H24: 2026 | I24: =C24*$P$2*$P$4/10^6 -> 804.27992 | J24: =D24*$P$2*$P$4/10^6 -> 921.51846 | K24: =E24*$P$2*$P$4/10^6 -> 1725.7984 | S24: 2026 | T24: 2800624 | U24: 3207826 | V24: =SUM(T24:U24) -> 6008450 | Y24: 2026 | Z24: =V24/E24 -> 1.1761989 | AA24: =Z24/$Z$8 -> 1.0133871 | AE24: 2026 | AF24: =C24*$AA24 -> 2412538.2 | AG24: =D24*$AA24 -> 2764209.9 | AH24: =E24*$AA24 -> 5176748.1 | AK24: 2026 | AL24: =AF24*$P$2*$P$4/10^6 -> 815.04688 | AM24: =AG24*$P$2*$P$4/10^6 -> 933.85491 | AN24: =AH24*$P$2*$P$4/10^6 -> 1748.9018
B25: 2027 | C25: 2384938 | D25: 2727654 | E25: 5112592 | H25: 2027 | I25: =C25*$P$2*$P$4/10^6 -> 805.72249 | J25: =D25*$P$2*$P$4/10^6 -> 921.50494 | K25: =E25*$P$2*$P$4/10^6 -> 1727.2274 | S25: 2027 | T25: 2816435 | U25: 3218373 | V25: =SUM(T25:U25) -> 6034808 | Y25: 2027 | Z25: =V25/E25 -> 1.1803813 | AA25: =Z25/$Z$8 -> 1.0169905 | AE25: 2027 | AF25: =C25*$AA25 -> 2425459.3 | AG25: =D25*$AA25 -> 2773998.2 | AH25: =E25*$AA25 -> 5199457.6 | AK25: 2027 | AL25: =AF25*$P$2*$P$4/10^6 -> 819.41212 | AM25: =AG25*$P$2*$P$4/10^6 -> 937.16179 | AN25: =AH25*$P$2*$P$4/10^6 -> 1756.5739
B26: 2028 | C26: 2387429 | D26: 2726434 | E26: 5113863 | H26: 2028 | I26: =C26*$P$2*$P$4/10^6 -> 806.56404 | J26: =D26*$P$2*$P$4/10^6 -> 921.09278 | K26: =E26*$P$2*$P$4/10^6 -> 1727.6568 | S26: 2028 | T26: 2831787 | U26: 3228682 | V26: =SUM(T26:U26) -> 6060469 | Y26: 2028 | Z26: =V26/E26 -> 1.1851059 | AA26: =Z26/$Z$8 -> 1.0210611 | AE26: 2028 | AF26: =C26*$AA26 -> 2437710.8 | AG26: =D26*$AA26 -> 2783855.7 | AH26: =E26*$AA26 -> 5221566.5 | AK26: 2028 | AL26: =AF26*$P$2*$P$4/10^6 -> 823.55115 | AM26: =AG26*$P$2*$P$4/10^6 -> 940.492 | AN26: =AH26*$P$2*$P$4/10^6 -> 1764.0432
B27: 2029 | C27: 2389346 | D27: 2725037 | E27: 5114383 | H27: 2029 | I27: =C27*$P$2*$P$4/10^6 -> 807.21167 | J27: =D27*$P$2*$P$4/10^6 -> 920.62082 | K27: =E27*$P$2*$P$4/10^6 -> 1727.8325 | S27: 2029 | T27: 2846649 | U27: 3238601 | V27: =SUM(T27:U27) -> 6085250 | Y27: 2029 | Z27: =V27/E27 -> 1.1898307 | AA27: =Z27/$Z$8 -> 1.0251319 | AE27: 2029 | AF27: =C27*$AA27 -> 2449394.9 | AG27: =D27*$AA27 -> 2793522.4 | AH27: =E27*$AA27 -> 5242917.3 | AK27: 2029 | AL27: =AF27*$P$2*$P$4/10^6 -> 827.49846 | AM27: =AG27*$P$2*$P$4/10^6 -> 943.75779 | AN27: =AH27*$P$2*$P$4/10^6 -> 1771.2562
... B43: 2045 | C43: 2448973 | D43: 2753635 | E43: 5202608 | H43: 2045 | I43: =C43*$P$2*$P$4/10^6 -> 827.35594 | J43: =D43*$P$2*$P$4/10^6 -> 930.28231 | K43: =E43*$P$2*$P$4/10^6 -> 1757.6382 | S43: 2045 | T43: 3016481 | U43: 3346842 | V43: =SUM(T43:U43) -> 6363323 | Y43: 2045 | Z43: =V43/E43 -> 1.2231025 | AA43: =Z43/$Z$8 -> 1.0537982 | AE43: 2045 | AF43: =C43*$AA43 -> 2580723.3 | AG43: =D43*$AA43 -> 2901775.6 | AH43: =E43*$AA43 -> 5482498.8 | AK43: 2045 | AL43: =AF43*$P$2*$P$4/10^6 -> 871.86618 | AM43: =AG43*$P$2*$P$4/10^6 -> 980.32981 | AN43: =AH43*$P$2*$P$4/10^6 -> 1852.196
B44: 2046 | C44: 2448973 | D44: 2753635 | E44: 5202608 | H44: 2046 | I44: =C44*$P$2*$P$4/10^6 -> 827.35594 | J44: =D44*$P$2*$P$4/10^6 -> 930.28231 | K44: =E44*$P$2*$P$4/10^6 -> 1757.6382 | S44: 2046 | T44: =T43 -> 3016481 | U44: =U43 -> 3346842 | V44: =SUM(T44:U44) -> 6363323 | Y44: 2046 | Z44: =V44/E44 -> 1.2231025 | AA44: =Z44/$Z$8 -> 1.0537982 | AE44: 2046 | AF44: =C44*$AA44 -> 2580723.3 | AG44: =D44*$AA44 -> 2901775.6 | AH44: =E44*$AA44 -> 5482498.8 | AK44: 2046 | AL44: =AF44*$P$2*$P$4/10^6 -> 871.86618 | AM44: =AG44*$P$2*$P$4/10^6 -> 980.32981 | AN44: =AH44*$P$2*$P$4/10^6 -> 1852.196
B45: 2047 | C45: 2448973 | D45: 2753635 | E45: 5202608 | H45: 2047 | I45: =C45*$P$2*$P$4/10^6 -> 827.35594 | J45: =D45*$P$2*$P$4/10^6 -> 930.28231 | K45: =E45*$P$2*$P$4/10^6 -> 1757.6382 | S45: 2047 | T45: =T44 -> 3016481 | U45: =U44 -> 3346842 | V45: =SUM(T45:U45) -> 6363323 | Y45: 2047 | Z45: =V45/E45 -> 1.2231025 | AA45: =Z45/$Z$8 -> 1.0537982 | AE45: 2047 | AF45: =C45*$AA45 -> 2580723.3 | AG45: =D45*$AA45 -> 2901775.6 | AH45: =E45*$AA45 -> 5482498.8 | AK45: 2047 | AL45: =AF45*$P$2*$P$4/10^6 -> 871.86618 | AM45: =AG45*$P$2*$P$4/10^6 -> 980.32981 | AN45: =AH45*$P$2*$P$4/10^6 -> 1852.196
B46: 2048 | C46: 2448973 | D46: 2753635 | E46: 5202608 | H46: 2048 | I46: =C46*$P$2*$P$4/10^6 -> 827.35594 | J46: =D46*$P$2*$P$4/10^6 -> 930.28231 | K46: =E46*$P$2*$P$4/10^6 -> 1757.6382 | S46: 2048 | T46: =T45 -> 3016481 | U46: =U45 -> 3346842 | V46: =SUM(T46:U46) -> 6363323 | Y46: 2048 | Z46: =V46/E46 -> 1.2231025 | AA46: =Z46/$Z$8 -> 1.0537982 | AE46: 2048 | AF46: =C46*$AA46 -> 2580723.3 | AG46: =D46*$AA46 -> 2901775.6 | AH46: =E46*$AA46 -> 5482498.8 | AK46: 2048 | AL46: =AF46*$P$2*$P$4/10^6 -> 871.86618 | AM46: =AG46*$P$2*$P$4/10^6 -> 980.32981 | AN46: =AH46*$P$2*$P$4/10^6 -> 1852.196
B47: 2049 | C47: 2448973 | D47: 2753635 | E47: 5202608 | H47: 2049 | I47: =C47*$P$2*$P$4/10^6 -> 827.35594 | J47: =D47*$P$2*$P$4/10^6 -> 930.28231 | K47: =E47*$P$2*$P$4/10^6 -> 1757.6382 | S47: 2049 | T47: =T46 -> 3016481 | U47: =U46 -> 3346842 | V47: =SUM(T47:U47) -> 6363323 | Y47: 2049 | Z47: =V47/E47 -> 1.2231025 | AA47: =Z47/$Z$8 -> 1.0537982 | AE47: 2049 | AF47: =C47*$AA47 -> 2580723.3 | AG47: =D47*$AA47 -> 2901775.6 | AH47: =E47*$AA47 -> 5482498.8 | AK47: 2049 | AL47: =AF47*$P$2*$P$4/10^6 -> 871.86618 | AM47: =AG47*$P$2*$P$4/10^6 -> 980.32981 | AN47: =AH47*$P$2*$P$4/10^6 -> 1852.196
B48: 2050 | C48: 2448973 | D48: 2753635 | E48: 5202608 | H48: 2050 | I48: =C48*$P$2*$P$4/10^6 -> 827.35594 | J48: =D48*$P$2*$P$4/10^6 -> 930.28231 | K48: =E48*$P$2*$P$4/10^6 -> 1757.6382 | S48: 2050 | T48: =T47 -> 3016481 | U48: =U47 -> 3346842 | V48: =SUM(T48:U48) -> 6363323 | Y48: 2050 | Z48: =V48/E48 -> 1.2231025 | AA48: =Z48/$Z$8 -> 1.0537982 | AE48: 2050 | AF48: =C48*$AA48 -> 2580723.3 | AG48: =D48*$AA48 -> 2901775.6 | AH48: =E48*$AA48 -> 5482498.8 | AK48: 2050 | AL48: =AF48*$P$2*$P$4/10^6 -> 871.86618 | AM48: =AG48*$P$2*$P$4/10^6 -> 980.32981 | AN48: =AH48*$P$2*$P$4/10^6 -> 1852.196

Sheet TTB from TIMES population
B2: Data on population projections from statistics denmark | J2: MINTTB East | L2: 642.0953
B3: http://www.statistikbanken.dk/statbank5a/default.asp?w=1920 | J3: MINTTB West | L3: 747.7762
B5: Population projection | J5: Travel time budget calibrated with results of first run
C6: DKE | D6: DKW | E6: Total | G6: Population relative growth | K6: DKE | L6: DKW | M6: Total
B7: 2010 | C7: =E7*$C$15/$E$15 -> 2544463.5 | D7: =E7*$D$15/$E$15 -> 2990536.5 | E7: 5535000 | G7: 1 | H7: 1 | I7: =E7/$E$7 -> 1 | J7: 2010 | K7: =$L$2*G7 -> 642.0953 | L7: =$L$3*H7 -> 747.7762 | M7: =SUM(K7:L7) -> 1389.8715 | P7: Attribute | Q7: Year | R7: DKE | S7: DKW | T7: Pset_PN
B8: 2011 | C8: =E8*$C$15/$E$15 -> 2556415.9 | D8: =E8*$D$15/$E$15 -> 3004584.1 | E8: 5561000 | G8: =C8/$C$7 -> 1.0046974 | H8: =D8/$D$7 -> 1.0046974 | I8: =E8/$E$7 -> 1.0046974 | J8: 2011 | K8: =$L$2*G8 -> 645.11147 | L8: =$L$3*H8 -> 751.28879 | M8: =SUM(K8:L8) -> 1396.4003 | P8: ACT_BND | Q8: 2010 | R8: =K7 -> 642.0953 | S8: =L7 -> 747.7762 | T8: MINTTB | X8: Travel time budget calculations based on historical surveys made for denmark on travel time
B9: 2012 | C9: =E9*$C$15/$E$15 -> 2565609.9 | D9: =E9*$D$15/$E$15 -> 3015390.1 | E9: 5581000 | G9: =C9/$C$7 -> 1.0083107 | H9: =D9/$D$7 -> 1.0083107 | I9: =E9/$E$7 -> 1.0083107 | J9: 2012 | K9: =$L$2*G9 -> 647.43159 | L9: =$L$3*H9 -> 753.99078 | M9: =SUM(K9:L9) -> 1401.4224 | P9: ACT_BND | Q9: 2020 | R9: =$R$8*G17 -> 680.86949 | S9: =$S$8*H17 -> 786.81925 | T9: MINTTB | X9: 54.8 | Y9: min | Z9: https://www.sciencedirect.com/science/article/pii/S0301421517307474?via%3Dihub
B10: 2013 | C10: =E10*$C$15/$E$15 -> 2575723.4 | D10: =E10*$D$15/$E$15 -> 3027276.6 | E10: 5603000 | G10: =C10/$C$7 -> 1.0122855 | H10: =D10/$D$7 -> 1.0122855 | I10: =E10/$E$7 -> 1.0122855 | J10: 2013 | K10: =$L$2*G10 -> 649.98373 | L10: =$L$3*H10 -> 756.96297 | M10: =SUM(K10:L10) -> 1406.9467 | P10: ACT_BND | Q10: 2030 | R10: =$R$8*G27 -> 721.96948 | S10: =$S$8*H27 -> 812.18032 | T10: MINTTB | X10: =X9/60 -> 0.91333333 | Y10: Hours per day/person
B11: 2014 | C11: =E11*$C$15/$E$15 -> 2575723.4 | D11: =E11*$D$15/$E$15 -> 3027276.6 | E11: 5603000 | G11: =C11/$C$7 -> 1.0122855 | H11: =D11/$D$7 -> 1.0122855 | I11: =E11/$E$7 -> 1.0122855 | J11: 2014 | K11: =$L$2*G11 -> 649.98373 | L11: =$L$3*H11 -> 756.96297 | M11: =SUM(K11:L11) -> 1406.9467 | P11: ACT_BND | Q11: 2040 | R11: =$R$8*G37 -> 750.5731 | S11: =$S$8*H37 -> 830.62958 | T11: MINTTB
B12: 2015 | C12: =E12*$C$15/$E$15 -> 2586756.3 | D12: =E12*$D$15/$E$15 -> 3040243.7 | E12: 5627000 | G12: =C12/$C$7 -> 1.0166215 | H12: =D12/$D$7 -> 1.0166215 | I12: =E12/$E$7 -> 1.0166215 | J12: 2015 | K12: =$L$2*G12 -> 652.76789 | L12: =$L$3*H12 -> 760.20536 | M12: =SUM(K12:L12) -> 1412.9732 | P12: ACT_BND | Q12: 2050 | R12: =$R$8*G47 -> 761.20889 | S12: =$S$8*H47 -> 836.86951 | T12: MINTTB | X12: =X10*365 -> 333.36667 | Y12: Hours per year/person
B13: 2016 | C13: =E13*$C$15/$E$15 -> 2623532.7 | D13: =E13*$D$15/$E$15 -> 3083467.3 | E13: 5707000 | G13: =C13/$C$7 -> 1.031075 | H13: =D13/$D$7 -> 1.031075 | I13: =E13/$E$7 -> 1.031075 | J13: 2016 | K13: =$L$2*G13 -> 662.0484 | L13: =$L$3*H13 -> 771.01333 | M13: =SUM(K13:L13) -> 1433.0617 | P13: ACT_BND | Q13: 0 | R13: 5 | S13: 5 | T13: MINTTB | X13: DKE | Y13: DKW
B14: 2017 | C14: =E14*$C$15/$E$15 -> 2642840.3 | D14: =E14*$D$15/$E$15 -> 3106159.7 | E14: 5749000 | G14: =C14/$C$7 -> 1.0386631 | H14: =D14/$D$7 -> 1.0386631 | I14: =E14/$E$7 -> 1.0386631 | J14: 2017 | K14: =$L$2*G14 -> 666.92066 | L14: =$L$3*H14 -> 776.68751 | M14: =SUM(K14:L14) -> 1443.6082 | X14: =X12*C7 -> 8.4823933e+08 | Y14: =X12*D7 -> 9.9694517e+08
B15: 2018 | C15: 2657600 | D15: 3123507 | E15: =SUM(C15:D15) -> 5781107 | G15: =C15/$C$7 -> 1.0444638 | H15: =D15/$D$7 -> 1.0444638 | I15: =E15/$E$7 -> 1.0444638 | J15: 2018 | K15: =$L$2*G15 -> 670.64528 | L15: =$L$3*H15 -> 781.02515 | M15: =SUM(K15:L15) -> 1451.6704
B16: 2019 | C16: 2678707 | D16: 3135513 | E16: =SUM(C16:D16) -> 5814220 | G16: =C16/$C$7 -> 1.052759 | H16: =D16/$D$7 -> 1.0484784 | I16: =E16/$E$7 -> 1.0504463 | J16: 2019 | K16: =$L$2*G16 -> 675.97163 | L16: =$L$3*H16 -> 784.02722 | M16: =SUM(K16:L16) -> 1459.9989
B17: 2020 | C17: 2698116 | D17: 3146679 | E17: =SUM(C17:D17) -> 5844795 | G17: =C17/$C$7 -> 1.060387 | H17: =D17/$D$7 -> 1.0522122 | I17: =E17/$E$7 -> 1.0559702 | J17: 2020 | K17: =$L$2*G17 -> 680.86949 | L17: =$L$3*H17 -> 786.81925 | M17: =SUM(K17:L17) -> 1467.6887
B18: 2021 | C18: 2716720 | D18: 3156661 | E18: =SUM(C18:D18) -> 5873381 | G18: =C18/$C$7 -> 1.0676985 | H18: =D18/$D$7 -> 1.0555501 | I18: =E18/$E$7 -> 1.0611348 | J18: 2021 | K18: =$L$2*G18 -> 685.56421 | L18: =$L$3*H18 -> 789.31523 | M18: =SUM(K18:L18) -> 1474.8794
B19: 2022 | C19: 2734303 | D19: 3166511 | E19: =SUM(C19:D19) -> 5900814 | G19: =C19/$C$7 -> 1.0746088 | H19: =D19/$D$7 -> 1.0588438 | I19: =E19/$E$7 -> 1.0660911 | J19: 2022 | K19: =$L$2*G19 -> 690.00128 | L19: =$L$3*H19 -> 791.7782 | M19: =SUM(K19:L19) -> 1481.7795
B20: 2023 | C20: 2751292 | D20: 3176484 | E20: =SUM(C20:D20) -> 5927776 | G20: =C20/$C$7 -> 1.0812857 | H20: =D20/$D$7 -> 1.0621787 | I20: =E20/$E$7 -> 1.0709622 | J20: 2023 | K20: =$L$2*G20 -> 694.28846 | L20: =$L$3*H20 -> 794.27192 | M20: =SUM(K20:L20) -> 1488.5604
B21: 2024 | C21: 2767951 | D21: 3186720 | E21: =SUM(C21:D21) -> 5954671 | G21: =C21/$C$7 -> 1.0878328 | H21: =D21/$D$7 -> 1.0656015 | I21: =E21/$E$7 -> 1.0758213 | J21: 2024 | K21: =$L$2*G21 -> 698.49235 | L21: =$L$3*H21 -> 796.83141 | M21: =SUM(K21:L21) -> 1495.3238
B22: 2025 | C22: 2784425 | D22: 3197217 | E22: =SUM(C22:D22) -> 5981642 | G22: =C22/$C$7 -> 1.0943073 | H22: =D22/$D$7 -> 1.0691115 | I22: =E22/$E$7 -> 1.0806941 | J22: 2025 | K22: =$L$2*G22 -> 702.64957 | L22: =$L$3*H22 -> 799.45616 | M22: =SUM(K22:L22) -> 1502.1057
B23: 2026 | C23: 2800624 | D23: 3207826 | E23: =SUM(C23:D23) -> 6008450 | G23: =C23/$C$7 -> 1.1006737 | H23: =D23/$D$7 -> 1.0726591 | I23: =E23/$E$7 -> 1.0855375 | J23: 2026 | K23: =$L$2*G23 -> 706.73738 | L23: =$L$3*H23 -> 802.10891 | M23: =SUM(K23:L23) -> 1508.8463
B24: 2027 | C24: 2816435 | D24: 3218373 | E24: =SUM(C24:D24) -> 6034808 | G24: =C24/$C$7 -> 1.1068875 | H24: =D24/$D$7 -> 1.0761858 | I24: =E24/$E$7 -> 1.0902995 | J24: 2027 | K24: =$L$2*G24 -> 710.72729 | L24: =$L$3*H24 -> 804.74616 | M24: =SUM(K24:L24) -> 1515.4734
B25: 2028 | C25: 2831787 | D25: 3228682 | E25: =SUM(C25:D25) -> 6060469 | G25: =C25/$C$7 -> 1.112921 | H25: =D25/$D$7 -> 1.0796331 | I25: =E25/$E$7 -> 1.0949357 | J25: 2028 | K25: =$L$2*G25 -> 714.60137 | L25: =$L$3*H25 -> 807.3239 | M25: =SUM(K25:L25) -> 1521.9253
B26: 2029 | C26: 2846649 | D26: 3238601 | E26: =SUM(C26:D26) -> 6085250 | G26: =C26/$C$7 -> 1.118762 | H26: =D26/$D$7 -> 1.0829498 | I26: =E26/$E$7 -> 1.0994128 | J26: 2029 | K26: =$L$2*G26 -> 718.35179 | L26: =$L$3*H26 -> 809.80412 | M26: =SUM(K26:L26) -> 1528.1559
... B42: 2045 | C42: 3016481 | D42: 3346842 | E42: =SUM(C42:D42) -> 6363323 | G42: =C42/$C$7 -> 1.1855077 | H42: =D42/$D$7 -> 1.1191444 | I42: =E42/$E$7 -> 1.1496519 | J42: 2045 | K42: =$L$2*G42 -> 761.20889 | L42: =$L$3*H42 -> 836.86951 | M42: =SUM(K42:L42) -> 1598.0784
B43: 2046 | C43: =C42 -> 3016481 | D43: =D42 -> 3346842 | E43: =SUM(C43:D43) -> 6363323 | G43: =C43/$C$7 -> 1.1855077 | H43: =D43/$D$7 -> 1.1191444 | I43: =E43/$E$7 -> 1.1496519 | J43: 2046 | K43: =$L$2*G43 -> 761.20889 | L43: =$L$3*H43 -> 836.86951 | M43: =SUM(K43:L43) -> 1598.0784
B44: 2047 | C44: =C43 -> 3016481 | D44: =D43 -> 3346842 | E44: =SUM(C44:D44) -> 6363323 | G44: =C44/$C$7 -> 1.1855077 | H44: =D44/$D$7 -> 1.1191444 | I44: =E44/$E$7 -> 1.1496519 | J44: 2047 | K44: =$L$2*G44 -> 761.20889 | L44: =$L$3*H44 -> 836.86951 | M44: =SUM(K44:L44) -> 1598.0784
B45: 2048 | C45: =C44 -> 3016481 | D45: =D44 -> 3346842 | E45: =SUM(C45:D45) -> 6363323 | G45: =C45/$C$7 -> 1.1855077 | H45: =D45/$D$7 -> 1.1191444 | I45: =E45/$E$7 -> 1.1496519 | J45: 2048 | K45: =$L$2*G45 -> 761.20889 | L45: =$L$3*H45 -> 836.86951 | M45: =SUM(K45:L45) -> 1598.0784
B46: 2049 | C46: =C45 -> 3016481 | D46: =D45 -> 3346842 | E46: =SUM(C46:D46) -> 6363323 | G46: =C46/$C$7 -> 1.1855077 | H46: =D46/$D$7 -> 1.1191444 | I46: =E46/$E$7 -> 1.1496519 | J46: 2049 | K46: =$L$2*G46 -> 761.20889 | L46: =$L$3*H46 -> 836.86951 | M46: =SUM(K46:L46) -> 1598.0784
B47: 2050 | C47: =C46 -> 3016481 | D47: =D46 -> 3346842 | E47: =SUM(C47:D47) -> 6363323 | G47: =C47/$C$7 -> 1.1855077 | H47: =D47/$D$7 -> 1.1191444 | I47: =E47/$E$7 -> 1.1496519 | J47: 2050 | K47: =$L$2*G47 -> 761.20889 | L47: =$L$3*H47 -> 836.86951 | M47: =SUM(K47:L47) -> 1598.0784

Sheet Speed
B2: From Transport base constraint
O3: Modal speed by trip distance [km/h]
P4: Extra Short | Q4: Short | R4: Medium | S4: Long
B5: Attribute | C5: PSET_PN | D5: CSET_CN | E5: DKE | F5: DKW | O5: Car | P5: =X15 -> 30.314584 | Q5: =X16 -> 48.43151 | R5: 63.011105 | S5: 78.386393
C6: TPCA* | D6: TIMECXS, TIMECS, TIMECM, TIMECL | E6: IN | F6: IN | O6: Bus | P6: 20.980333 | Q6: 31.407178 | R6: 47.350725 | S6: 64.917008
C7: TPBU* | D7: TIMEBXS, TIMEBS, TIMEBM, TIMEBL | E7: IN | F7: IN | O7: Coach | Q7: 36.782436 | R7: 58.592852 | S7: 70.68684 | W7: km/h | X7: counts | Y7: weigth
C8: TPCO* | D8: TIMEBXS, TIMEBS, TIMEBM, TIMEBL | E8: IN | F8: IN | O8: Train | Q8: 60.840995 | R8: 70.819516 | S8: 91.327718 | V8: 0-3 km | W8: 26.75266 | X8: 62084 | Y8: 339.6934
C9: TPMT* | D9: TIMEMTS, TIMEMTM, TIMEMTL | E9: IN | F9: IN | O9: S-train | P9: 36.10735 | Q9: 45.280434 | R9: 55.080236 | V9: 3-5 km | W9: 37.33909 | X9: 31481 | Y9: 342.7629
C10: TPMP* | D10: TIMEMPXS, TIMEMPS, TIMEMPM, TIMEMPL | E10: IN | F10: IN | O10: Metro | P10: 31.721662 | Q10: 39.654932 | V10: 5-9 km | W10: 41.88586 | X10: 32834 | Y10: 342.7629
C11: TPRO* | D11: TIMETS, TIMETM, TIMETL | E11: IN | F11: IN | O11: Motorbike | Q11: 45.35444 | R11: 63.606779 | S11: 72.618478 | V11: 9-17 km | W11: 49.69223 | X11: 40352 | Y11: 343.9822
C12: TPRS* | D12: TIMESTXS, TIMESTS, TIMESTM | E12: IN | F12: IN | O12: Mopeds | P12: 26.820397 | Q12: 37.854797 | R12: 41.142393 | S12: 60.375 | V12: 17-25 km | W12: 56.14775 | X12: 21260 | Y12: 342.797
C13: TPRM* | D13: TIMEMEXS, TIMEMES | E13: IN | F13: IN | O13: Bike | P13: 15.830551 | Q13: 18.469142
C14: TPW* | D14: TIMEWXS, TIMEWS | E14: IN | F14: IN | O14: ElBike | P14: =25*0.7 -> 17.5 | Q14: =25*0.75 -> 18.75 | R14: =25*0.8 -> 20
C15: TPBIKING* | D15: TIMEBIXS,TIMEBIS | E15: IN | F15: IN | O15: Walk | P15: 5.9817794 | Q15: 5.9817794 | V15: extra short | W15: =W8*0.6+W9*0.4 -> 30.987232 | X15: =(W8*X8+W9*X9)/SUM(X8:X9) -> 30.314584 | Y15: =(W8*Y8+W9*Y9)/SUM(Y8:Y9) -> 32.069682
C16: TPELBIK1N | D16: TIMEBIXS,TIMEBIS,TIMEBIM | E16: IN | F16: IN | O16: Airplane | S16: 330.29319 | V16: short | W16: =W10*0.2+W11*0.3+W12*0.3 -> 40.129166 | X16: =(W10*X10+W11*X11+W12*X12)/SUM(X10:X12) -> 48.43151 | Y16: =(W10*Y10+W11*Y11+W12*Y12)/SUM(Y10:Y12) -> 49.242709
O17: Ship | Q17: 25 | R17: 25 | S17: 25
M19: Travel demands | AB19: Travel time budgets
M20: 2010 | N20: 2010 | O20: 2010 | P20: 2020 | Q20: 2020 | R20: 2020 | S20: 2030 | T20: =S20 -> 2030 | U20: =T20 -> 2030 | V20: 2040 | W20: =V20 -> 2040 | X20: =W20 -> 2040 | Y20: 2050 | Z20: =Y20 -> 2050 | AA20: =Z20 -> 2050 | AB20: =M20 -> 2010 | AC20: =N20 -> 2010 | AD20: =O20 -> 2010 | AE20: =P20 -> 2020 | AF20: =Q20 -> 2020 | AG20: =R20 -> 2020 | AH20: =S20 -> 2030 | AI20: =T20 -> 2030 | ... AP20: =AA20 -> 2050
C21: Attribute | D21: Year | E21: DKE | F21: DKW | G21: Pset_PN | H21: Other_Indexes | I21: Cset_CN | M21: DK | N21: DKE | O21: DKW | P21: DK | Q21: DKE | R21: DKW | S21: DK | T21: DKE | U21: DKW | V21: DK | W21: DKE | X21: DKW | Y21: DK | Z21: DKE | AA21: DKW | AB21: DK TT | AC21: DKE tt | AD21: DKWtt | AE21: DK TT | AF21: DKE tt | AG21: DKWtt | AH21: DK TT | AI21: DKE tt | AJ21: DKWtt | AK21: DK TT | AL21: DKE tt | AM21: DKWtt | AN21: DK TT | AO21: DKE tt | AP21: DKWtt
C22: FLO_FUNC | D22: 2010 | E22: =1/$P$5 -> 0.032987423 | F22: =1/$P$5 -> 0.032987423 | G22: TPCA* | H22: TPXS | I22: TIMECXS | K22: Car | M22: {=INDEX('LTM data'!$D$47:$W$66,MATCH(Speed!$H22&Speed!M$20,'LTM data'!$C$47:$C$66&'LTM data'!$A$47:$A$66,0),MATCH(Speed!$K22,'LTM data'!$D$46:$W$46,0))} -> 3299.2425 | N22: {=INDEX('LTM data'!$D$47:$W$66,MATCH(Speed!$H22&Speed!N$20,'LTM data'!$C$47:$C$66&'LTM data'!$A$47:$A$66,0),MATCH((Speed!$K22&" DKE"),'LTM data'!$D$46:$W$46,0))} -> 1315.3946 | O22: =M22-N22 -> 1983.8479 | P22: {=INDEX('LTM data'!$D$47:$W$66,MATCH(Speed!$H22&Speed!P$20,'LTM data'!$C$47:$C$66&'LTM data'!$A$47:$A$66,0),MATCH(Speed!$K22,'LTM data'!$D$46:$W$46,0))} -> 4032.4864 | Q22: {=INDEX('LTM data'!$D$47:$W$66,MATCH(Speed!$H22&Speed!Q$20,'LTM data'!$C$47:$C$66&'LTM data'!$A$47:$A$66,0),MATCH((Speed!$K22&" DKE"),'LTM data'!$D$46:$W$46,0))} -> 1607.7359 | R22: =P22-Q22 -> 2424.7504 | S22: {=INDEX('LTM data'!$D$47:$W$66,MATCH(Speed!$H22&Speed!S$20,'LTM data'!$C$47:$C$66&'LTM data'!$A$47:$A$66,0),MATCH(Speed!$K22,'LTM data'!$D$46:$W$46,0))} -> 4204.7338 | T22: {=INDEX('LTM data'!$D$47:$W$66,MATCH(Speed!$H22&Speed!T$20,'LTM data'!$C$47:$C$66&'LTM data'!$A$47:$A$66,0),MATCH((Speed!$K22&" DKE"),'LTM data'!$D$46:$W$46,0))} -> 1676.4103 | U22: =S22-T22 -> 2528.3236 | V22: {=INDEX('LTM data'!$D$47:$W$66,MATCH(Speed!$H22&Speed!V$20,'LTM data'!$C$47:$C$66&'LTM data'!$A$47:$A$66,0),MATCH(Speed!$K22,'LTM data'!$D$46:$W$46,0))} -> 4519.7927 | W22: {=INDEX('LTM data'!$D$47:$W$66,MATCH(Speed!$H22&Speed!W$20,'LTM data'!$C$47:$C$66&'LTM data'!$A$47:$A$66,0),MATCH((Speed!$K22&" DKE"),'LTM data'!$D$46:$W$46,0))} -> 1802.023 | X22: =V22-W22 -> 2717.7697 | Y22: {=INDEX('LTM data'!$D$47:$W$66,MATCH(Speed!$H22&Speed!Y$20,'LTM data'!$C$47:$C$66&'LTM data'!$A$47:$A$66,0),MATCH(Speed!$K22,'LTM data'!$D$46:$W$46,0))} -> 4799.0015 | Z22: {=INDEX('LTM data'!$D$47:$W$66,MATCH(Speed!$H22&Speed!Z$20,'LTM data'!$C$47:$C$66&'LTM data'!$A$47:$A$66,0),MATCH((Speed!$K22&" DKE"),'LTM data'!$D$46:$W$46,0))} -> 1913.3424 | AA22: =Y22-Z22 -> 2885.6591 | AB22: =M22*$F22 -> 108.83351 | AC22: =$E22*N22 -> 43.391477 | AD22: =$F22*O22 -> 65.44203 | AE22: =P22*$F22 -> 133.02133 | AF22: =$E22*Q22 -> 53.035065 | AG22: =$F22*R22 -> 79.986268 | AH22: =S22*$F22 -> 138.70333 | AI22: =$E22*T22 -> 55.300456 | AJ22: =$F22*U22 -> 83.402878 | AK22: =V22*$F22 -> 149.09631 | AL22: =$E22*W22 -> 59.444094 | AM22: =$F22*X22 -> 89.652219 | AN22: =Y22*$F22 -> 158.30669 | AO22: =$E22*Z22 -> 63.116235 | AP22: =$F22*AA22 -> 95.190458
C23: FLO_FUNC | D23: 2010 | E23: =1/$Q$5 -> 0.020647715 | F23: =1/$Q$5 -> 0.020647715 | G23: TPCA* | H23: TPS | I23: TIMECS | K23: Car | M23: {=INDEX('LTM data'!$D$47:$W$66,MATCH(Speed!$H23&Speed!M$20,'LTM data'!$C$47:$C$66&'LTM data'!$A$47:$A$66,0),MATCH(Speed!$K23,'LTM data'!$D$46:$W$46,0))} -> 15830.087 | N23: {=INDEX('LTM data'!$D$47:$W$66,MATCH(Speed!$H23&Speed!N$20,'LTM data'!$C$47:$C$66&'LTM data'!$A$47:$A$66,0),MATCH((Speed!$K23&" DKE"),'LTM data'!$D$46:$W$46,0))} -> 6311.3791 | O23: =M23-N23 -> 9518.7083 | P23: {=INDEX('LTM data'!$D$47:$W$66,MATCH(Speed!$H23&Speed!P$20,'LTM data'!$C$47:$C$66&'LTM data'!$A$47:$A$66,0),MATCH(Speed!$K23,'LTM data'!$D$46:$W$46,0))} -> 19348.263 | Q23: {=INDEX('LTM data'!$D$47:$W$66,MATCH(Speed!$H23&Speed!Q$20,'LTM data'!$C$47:$C$66&'LTM data'!$A$47:$A$66,0),MATCH((Speed!$K23&" DKE"),'LTM data'!$D$46:$W$46,0))} -> 7714.0587 | R23: =P23-Q23 -> 11634.204 | S23: {=INDEX('LTM data'!$D$47:$W$66,MATCH(Speed!$H23&Speed!S$20,'LTM data'!$C$47:$C$66&'LTM data'!$A$47:$A$66,0),MATCH(Speed!$K23,'LTM data'!$D$46:$W$46,0))} -> 20174.723 | T23: {=INDEX('LTM data'!$D$47:$W$66,MATCH(Speed!$H23&Speed!T$20,'LTM data'!$C$47:$C$66&'LTM data'!$A$47:$A$66,0),MATCH((Speed!$K23&" DKE"),'LTM data'!$D$46:$W$46,0))} -> 8043.5645 | U23: =S23-T23 -> 12131.159 | V23: {=INDEX('LTM data'!$D$47:$W$66,MATCH(Speed!$H23&Speed!V$20,'LTM data'!$C$47:$C$66&'LTM data'!$A$47:$A$66,0),MATCH(Speed!$K23,'LTM data'!$D$46:$W$46,0))} -> 21686.406 | W23: {=INDEX('LTM data'!$D$47:$W$66,MATCH(Speed!$H23&Speed!W$20,'LTM data'!$C$47:$C$66&'LTM data'!$A$47:$A$66,0),MATCH((Speed!$K23&" DKE"),'LTM data'!$D$46:$W$46,0))} -> 8646.2651 | X23: =V23-W23 -> 13040.141 | Y23: {=INDEX('LTM data'!$D$47:$W$66,MATCH(Speed!$H23&Speed!Y$20,'LTM data'!$C$47:$C$66&'LTM data'!$A$47:$A$66,0),MATCH(Speed!$K23,'LTM data'!$D$46:$W$46,0))} -> 23026.078 | Z23: {=INDEX('LTM data'!$D$47:$W$66,MATCH(Speed!$H23&Speed!Z$20,'LTM data'!$C$47:$C$66&'LTM data'!$A$47:$A$66,0),MATCH((Speed!$K23&" DKE"),'LTM data'!$D$46:$W$46,0))} -> 9180.3856 | AA23: =Y23-Z23 -> 13845.692 | AB23: =M23*$F23 -> 326.85513 | AC23: =$E23*N23 -> 130.31556 | AD23: =$F23*O23 -> 196.53957 | AE23: =P23*$F23 -> 399.49742 | AF23: =$E23*Q23 -> 159.27769 | AG23: =$F23*R23 -> 240.21974 | AH23: =S23*$F23 -> 416.56194 | AI23: =$E23*T23 -> 166.08123 | AJ23: =$F23*U23 -> 250.48071 | AK23: =V23*$F23 -> 447.77474 | AL23: =$E23*W23 -> 178.52562 | AM23: =$F23*X23 -> 269.24912 | AN23: =Y23*$F23 -> 475.43589 | AO23: =$E23*Z23 -> 189.55398 | AP23: =$F23*AA23 -> 285.8819
C24: FLO_FUNC | D24: 2010 | E24: =1/$R$5 -> 0.015870218 | F24: =1/$R$5 -> 0.015870218 | G24: TPCA* | H24: TPM | I24: TIMECM | K24: Car | M24: {=INDEX('LTM data'!$D$47:$W$66,MATCH(Speed!$H24&Speed!M$20,'LTM data'!$C$47:$C$66&'LTM data'!$A$47:$A$66,0),MATCH(Speed!$K24,'LTM data'!$D$46:$W$46,0))} -> 11434.146 | N24: {=INDEX('LTM data'!$D$47:$W$66,MATCH(Speed!$H24&Speed!N$20,'LTM data'!$C$47:$C$66&'LTM data'!$A$47:$A$66,0),MATCH((Speed!$K24&" DKE"),'LTM data'!$D$46:$W$46,0))} -> 4558.756 | O24: =M24-N24 -> 6875.3904 | P24: {=INDEX('LTM data'!$D$47:$W$66,MATCH(Speed!$H24&Speed!P$20,'LTM data'!$C$47:$C$66&'LTM data'!$A$47:$A$66,0),MATCH(Speed!$K24,'LTM data'!$D$46:$W$46,0))} -> 13975.341 | Q24: {=INDEX('LTM data'!$D$47:$W$66,MATCH(Speed!$H24&Speed!Q$20,'LTM data'!$C$47:$C$66&'LTM data'!$A$47:$A$66,0),MATCH((Speed!$K24&" DKE"),'LTM data'!$D$46:$W$46,0))} -> 5571.9219 | R24: =P24-Q24 -> 8403.4194 | S24: {=INDEX('LTM data'!$D$47:$W$66,MATCH(Speed!$H24&Speed!S$20,'LTM data'!$C$47:$C$66&'LTM data'!$A$47:$A$66,0),MATCH(Speed!$K24,'LTM data'!$D$46:$W$46,0))} -> 14572.297 | T24: {=INDEX('LTM data'!$D$47:$W$66,MATCH(Speed!$H24&Speed!T$20,'LTM data'!$C$47:$C$66&'LTM data'!$A$47:$A$66,0),MATCH((Speed!$K24&" DKE"),'LTM data'!$D$46:$W$46,0))} -> 5809.9264 | U24: =S24-T24 -> 8762.3711 | V24: {=INDEX('LTM data'!$D$47:$W$66,MATCH(Speed!$H24&Speed!V$20,'LTM data'!$C$47:$C$66&'LTM data'!$A$47:$A$66,0),MATCH(Speed!$K24,'LTM data'!$D$46:$W$46,0))} -> 15664.193 | W24: {=INDEX('LTM data'!$D$47:$W$66,MATCH(Speed!$H24&Speed!W$20,'LTM data'!$C$47:$C$66&'LTM data'!$A$47:$A$66,0),MATCH((Speed!$K24&" DKE"),'LTM data'!$D$46:$W$46,0))} -> 6245.2615 | X24: =V24-W24 -> 9418.9316 | Y24: {=INDEX('LTM data'!$D$47:$W$66,MATCH(Speed!$H24&Speed!Y$20,'LTM data'!$C$47:$C$66&'LTM data'!$A$47:$A$66,0),MATCH(Speed!$K24,'LTM data'!$D$46:$W$46,0))} -> 16631.844 | Z24: {=INDEX('LTM data'!$D$47:$W$66,MATCH(Speed!$H24&Speed!Z$20,'LTM data'!$C$47:$C$66&'LTM data'!$A$47:$A$66,0),MATCH((Speed!$K24&" DKE"),'LTM data'!$D$46:$W$46,0))} -> 6631.0607 | AA24: =Y24-Z24 -> 10000.783 | AB24: =M24*$F24 -> 181.4624 | AC24: =$E24*N24 -> 72.348454 | AD24: =$F24*O24 -> 109.11395 | AE24: =P24*$F24 -> 221.79172 | AF24: =$E24*Q24 -> 88.427618 | AG24: =$F24*R24 -> 133.3641 | AH24: =S24*$F24 -> 231.26554 | AI24: =$E24*T24 -> 92.204801 | AJ24: =$F24*U24 -> 139.06074 | AK24: =V24*$F24 -> 248.59417 | AL24: =$E24*W24 -> 99.113665 | AM24: =$F24*X24 -> 149.4805 | AN24: =Y24*$F24 -> 263.951 | AO24: =$E24*Z24 -> 105.23638 | AP24: =$F24*AA24 -> 158.71462
C25: FLO_FUNC | D25: 2010 | E25: =1/$S$5 -> 0.012757316 | F25: =1/$S$5 -> 0.012757316 | G25: TPCA* | H25: TPL | I25: TIMECL | K25: Car | M25: {=INDEX('LTM data'!$D$47:$W$66,MATCH(Speed!$H25&Speed!M$20,'LTM data'!$C$47:$C$66&'LTM data'!$A$47:$A$66,0),MATCH(Speed!$K25,'LTM data'!$D$46:$W$46,0))} -> 21898.978 | N25: {=INDEX('LTM data'!$D$47:$W$66,MATCH(Speed!$H25&Speed!N$20,'LTM data'!$C$47:$C$66&'LTM data'!$A$47:$A$66,0),MATCH((Speed!$K25&" DKE"),'LTM data'!$D$46:$W$46,0))} -> 8730.9461 | O25: =M25-N25 -> 13168.032 | P25: {=INDEX('LTM data'!$D$47:$W$66,MATCH(Speed!$H25&Speed!P$20,'LTM data'!$C$47:$C$66&'LTM data'!$A$47:$A$66,0),MATCH(Speed!$K25,'LTM data'!$D$46:$W$46,0))} -> 26765.942 | Q25: {=INDEX('LTM data'!$D$47:$W$66,MATCH(Speed!$H25&Speed!Q$20,'LTM data'!$C$47:$C$66&'LTM data'!$A$47:$A$66,0),MATCH((Speed!$K25&" DKE"),'LTM data'!$D$46:$W$46,0))} -> 10671.365 | R25: =P25-Q25 -> 16094.576 | S25: {=INDEX('LTM data'!$D$47:$W$66,MATCH(Speed!$H25&Speed!S$20,'LTM data'!$C$47:$C$66&'LTM data'!$A$47:$A$66,0),MATCH(Speed!$K25,'LTM data'!$D$46:$W$46,0))} -> 27909.248 | T25: {=INDEX('LTM data'!$D$47:$W$66,MATCH(Speed!$H25&Speed!T$20,'LTM data'!$C$47:$C$66&'LTM data'!$A$47:$A$66,0),MATCH((Speed!$K25&" DKE"),'LTM data'!$D$46:$W$46,0))} -> 11127.192 | U25: =S25-T25 -> 16782.056 | V25: {=INDEX('LTM data'!$D$47:$W$66,MATCH(Speed!$H25&Speed!V$20,'LTM data'!$C$47:$C$66&'LTM data'!$A$47:$A$66,0),MATCH(Speed!$K25,'LTM data'!$D$46:$W$46,0))} -> 30000.475 | W25: {=INDEX('LTM data'!$D$47:$W$66,MATCH(Speed!$H25&Speed!W$20,'LTM data'!$C$47:$C$66&'LTM data'!$A$47:$A$66,0),MATCH((Speed!$K25&" DKE"),'LTM data'!$D$46:$W$46,0))} -> 11960.948 | X25: =V25-W25 -> 18039.528 | Y25: {=INDEX('LTM data'!$D$47:$W$66,MATCH(Speed!$H25&Speed!Y$20,'LTM data'!$C$47:$C$66&'LTM data'!$A$47:$A$66,0),MATCH(Speed!$K25,'LTM data'!$D$46:$W$46,0))} -> 31853.746 | Z25: {=INDEX('LTM data'!$D$47:$W$66,MATCH(Speed!$H25&Speed!Z$20,'LTM data'!$C$47:$C$66&'LTM data'!$A$47:$A$66,0),MATCH((Speed!$K25&" DKE"),'LTM data'!$D$46:$W$46,0))} -> 12699.832 | AA25: =Y25-Z25 -> 19153.914 | AB25: =M25*$F25 -> 279.37219 | AC25: =$E25*N25 -> 111.38344 | AD25: =$F25*O25 -> 167.98875 | AE25: =P25*$F25 -> 341.46158 | AF25: =$E25*Q25 -> 136.13798 | AG25: =$F25*R25 -> 205.3236 | AH25: =S25*$F25 -> 356.0471 | AI25: =$E25*T25 -> 141.95311 | AJ25: =$F25*U25 -> 214.09399 | AK25: =V25*$F25 -> 382.72555 | AL25: =$E25*W25 -> 152.58959 | AM25: =$F25*X25 -> 230.13596 | AN25: =Y25*$F25 -> 406.3683 | AO25: =$E25*Z25 -> 162.01577 | AP25: =$F25*AA25 -> 244.35254
C26: FLO_FUNC | D26: 2010 | E26: =1/$P$6 -> 0.047663686 | F26: =1/$P$6 -> 0.047663686 | G26: TPBU* | H26: TPXS | I26: TIMEBXS | K26: Public bus | M26: {=INDEX('LTM data'!$D$47:$W$66,MATCH(Speed!$H26&Speed!M$20,'LTM data'!$C$47:$C$66&'LTM data'!$A$47:$A$66,0),MATCH(Speed!$K26,'LTM data'!$D$46:$W$46,0))} -> 589.71317 | N26: {=INDEX('LTM data'!$D$47:$W$66,MATCH(Speed!$H26&Speed!N$20,'LTM data'!$C$47:$C$66&'LTM data'!$A$47:$A$66,0),MATCH((Speed!$K26&" DKE"),'LTM data'!$D$46:$W$46,0))} -> 352.72136 | O26: =M26-N26 -> 236.99181 | P26: {=INDEX('LTM data'!$D$47:$W$66,MATCH(Speed!$H26&Speed!P$20,'LTM data'!$C$47:$C$66&'LTM data'!$A$47:$A$66,0),MATCH(Speed!$K26,'LTM data'!$D$46:$W$46,0))} -> 638.71316 | Q26: {=INDEX('LTM data'!$D$47:$W$66,MATCH(Speed!$H26&Speed!Q$20,'LTM data'!$C$47:$C$66&'LTM data'!$A$47:$A$66,0),MATCH((Speed!$K26&" DKE"),'LTM data'!$D$46:$W$46,0))} -> 382.02941 | R26: =P26-Q26 -> 256.68375 | S26: {=INDEX('LTM data'!$D$47:$W$66,MATCH(Speed!$H26&Speed!S$20,'LTM data'!$C$47:$C$66&'LTM data'!$A$47:$A$66,0),MATCH(Speed!$K26,'LTM data'!$D$46:$W$46,0))} -> 656.41985 | T26: {=INDEX('LTM data'!$D$47:$W$66,MATCH(Speed!$H26&Speed!T$20,'LTM data'!$C$47:$C$66&'LTM data'!$A$47:$A$66,0),MATCH((Speed!$K26&" DKE"),'LTM data'!$D$46:$W$46,0))} -> 392.6202 | U26: =S26-T26 -> 263.79965 | V26: {=INDEX('LTM data'!$D$47:$W$66,MATCH(Speed!$H26&Speed!V$20,'LTM data'!$C$47:$C$66&'LTM data'!$A$47:$A$66,0),MATCH(Speed!$K26,'LTM data'!$D$46:$W$46,0))} -> 586.98369 | W26: {=INDEX('LTM data'!$D$47:$W$66,MATCH(Speed!$H26&Speed!W$20,'LTM data'!$C$47:$C$66&'LTM data'!$A$47:$A$66,0),MATCH((Speed!$K26&" DKE"),'LTM data'!$D$46:$W$46,0))} -> 351.08879 | X26: =V26-W26 -> 235.89489 | Y26: {=INDEX('LTM data'!$D$47:$W$66,MATCH(Speed!$H26&Speed!Y$20,'LTM data'!$C$47:$C$66&'LTM data'!$A$47:$A$66,0),MATCH(Speed!$K26,'LTM data'!$D$46:$W$46,0))} -> 539.24938 | Z26: {=INDEX('LTM data'!$D$47:$W$66,MATCH(Speed!$H26&Speed!Z$20,'LTM data'!$C$47:$C$66&'LTM data'!$A$47:$A$66,0),MATCH((Speed!$K26&" DKE"),'LTM data'!$D$46:$W$46,0))} -> 322.53778 | AA26: =Y26-Z26 -> 216.7116 | AB26: =M26*$F26 -> 28.107904 | AC26: =$E26*N26 -> 16.812 | AD26: =$F26*O26 -> 11.295903 | AE26: =P26*$F26 -> 30.443424 | AF26: =$E26*Q26 -> 18.20893 | AG26: =$F26*R26 -> 12.234494 | AH26: =S26*$F26 -> 31.28739 | AI26: =$E26*T26 -> 18.713726 | AJ26: =$F26*U26 -> 12.573664 | AK26: =V26*$F26 -> 27.977806 | AL26: =$E26*W26 -> 16.734186 | AM26: =$F26*X26 -> 11.24362 | AN26: =Y26*$F26 -> 25.702613 | AO26: =$E26*Z26 -> 15.373339 | AP26: =$F26*AA26 -> 10.329274
C27: FLO_FUNC | D27: 2010 | E27: =1/$Q$6 -> 0.031839855 | F27: =1/$Q$6 -> 0.031839855 | G27: TPBU* | H27: TPS | I27: TIMEBS | K27: Public bus | M27: {=INDEX('LTM data'!$D$47:$W$66,MATCH(Speed!$H27&Speed!M$20,'LTM data'!$C$47:$C$66&'LTM data'!$A$47:$A$66,0),MATCH(Speed!$K27,'LTM data'!$D$46:$W$46,0))} -> 1693.7605 | N27: {=INDEX('LTM data'!$D$47:$W$66,MATCH(Speed!$H27&Speed!N$20,'LTM data'!$C$47:$C$66&'LTM data'!$A$47:$A$66,0),MATCH((Speed!$K27&" DKE"),'LTM data'!$D$46:$W$46,0))} -> 1013.0781 | O27: =M27-N27 -> 680.68239 | P27: {=INDEX('LTM data'!$D$47:$W$66,MATCH(Speed!$H27&Speed!P$20,'LTM data'!$C$47:$C$66&'LTM data'!$A$47:$A$66,0),MATCH(Speed!$K27,'LTM data'!$D$46:$W$46,0))} -> 1834.4972 | Q27: {=INDEX('LTM data'!$D$47:$W$66,MATCH(Speed!$H27&Speed!Q$20,'LTM data'!$C$47:$C$66&'LTM data'!$A$47:$A$66,0),MATCH((Speed!$K27&" DKE"),'LTM data'!$D$46:$W$46,0))} -> 1097.256 | R27: =P27-Q27 -> 737.24112 | S27: {=INDEX('LTM data'!$D$47:$W$66,MATCH(Speed!$H27&Speed!S$20,'LTM data'!$C$47:$C$66&'LTM data'!$A$47:$A$66,0),MATCH(Speed!$K27,'LTM data'!$D$46:$W$46,0))} -> 1885.3539 | T27: {=INDEX('LTM data'!$D$47:$W$66,MATCH(Speed!$H27&Speed!T$20,'LTM data'!$C$47:$C$66&'LTM data'!$A$47:$A$66,0),MATCH((Speed!$K27&" DKE"),'LTM data'!$D$46:$W$46,0))} -> 1127.6747 | U27: =S27-T27 -> 757.67925 | V27: {=INDEX('LTM data'!$D$47:$W$66,MATCH(Speed!$H27&Speed!V$20,'LTM data'!$C$47:$C$66&'LTM data'!$A$47:$A$66,0),MATCH(Speed!$K27,'LTM data'!$D$46:$W$46,0))} -> 1685.921 | W27: {=INDEX('LTM data'!$D$47:$W$66,MATCH(Speed!$H27&Speed!W$20,'LTM data'!$C$47:$C$66&'LTM data'!$A$47:$A$66,0),MATCH((Speed!$K27&" DKE"),'LTM data'!$D$46:$W$46,0))} -> 1008.3891 | X27: =V27-W27 -> 677.53186 | Y27: {=INDEX('LTM data'!$D$47:$W$66,MATCH(Speed!$H27&Speed!Y$20,'LTM data'!$C$47:$C$66&'LTM data'!$A$47:$A$66,0),MATCH(Speed!$K27,'LTM data'!$D$46:$W$46,0))} -> 1548.8196 | Z27: {=INDEX('LTM data'!$D$47:$W$66,MATCH(Speed!$H27&Speed!Z$20,'LTM data'!$C$47:$C$66&'LTM data'!$A$47:$A$66,0),MATCH((Speed!$K27&" DKE"),'LTM data'!$D$46:$W$46,0))} -> 926.38553 | AA27: =Y27-Z27 -> 622.43404 | AB27: =M27*$F27 -> 53.92909 | AC27: =$E27*N27 -> 32.256261 | AD27: =$F27*O27 -> 21.672829 | AE27: =P27*$F27 -> 58.410125 | AF27: =$E27*Q27 -> 34.936474 | AG27: =$F27*R27 -> 23.473651 | AH27: =S27*$F27 -> 60.029396 | AI27: =$E27*T27 -> 35.904998 | AJ27: =$F27*U27 -> 24.124398 | AK27: =V27*$F27 -> 53.67948 | AL27: =$E27*W27 -> 32.106964 | AM27: =$F27*X27 -> 21.572516 | AN27: =Y27*$F27 -> 49.314191 | AO27: =$E27*Z27 -> 29.495982 | AP27: =$F27*AA27 -> 19.81821
C28: FLO_FUNC | D28: 2010 | E28: =1/$R$6 -> 0.021119001 | F28: =1/$R$6 -> 0.021119001 | G28: TPBU* | H28: TPM | I28: TIMEBM | K28: Public bus | M28: {=INDEX('LTM data'!$D$47:$W$66,MATCH(Speed!$H28&Speed!M$20,'LTM data'!$C$47:$C$66&'LTM data'!$A$47:$A$66,0),MATCH(Speed!$K28,'LTM data'!$D$46:$W$46,0))} -> 486.97387 | N28: {=INDEX('LTM data'!$D$47:$W$66,MATCH(Speed!$H28&Speed!N$20,'LTM data'!$C$47:$C$66&'LTM data'!$A$47:$A$66,0),MATCH((Speed!$K28&" DKE"),'LTM data'!$D$46:$W$46,0))} -> 291.27056 | O28: =M28-N28 -> 195.70331 | P28: {=INDEX('LTM data'!$D$47:$W$66,MATCH(Speed!$H28&Speed!P$20,'LTM data'!$C$47:$C$66&'LTM data'!$A$47:$A$66,0),MATCH(Speed!$K28,'LTM data'!$D$46:$W$46,0))} -> 527.43713 | Q28: {=INDEX('LTM data'!$D$47:$W$66,MATCH(Speed!$H28&Speed!Q$20,'LTM data'!$C$47:$C$66&'LTM data'!$A$47:$A$66,0),MATCH((Speed!$K28&" DKE"),'LTM data'!$D$46:$W$46,0))} -> 315.47259 | R28: =P28-Q28 -> 211.96454 | S28: {=INDEX('LTM data'!$D$47:$W$66,MATCH(Speed!$H28&Speed!S$20,'LTM data'!$C$47:$C$66&'LTM data'!$A$47:$A$66,0),MATCH(Speed!$K28,'LTM data'!$D$46:$W$46,0))} -> 542.05897 | T28: {=INDEX('LTM data'!$D$47:$W$66,MATCH(Speed!$H28&Speed!T$20,'LTM data'!$C$47:$C$66&'LTM data'!$A$47:$A$66,0),MATCH((Speed!$K28&" DKE"),'LTM data'!$D$46:$W$46,0))} -> 324.21826 | U28: =S28-T28 -> 217.84071 | V28: {=INDEX('LTM data'!$D$47:$W$66,MATCH(Speed!$H28&Speed!V$20,'LTM data'!$C$47:$C$66&'LTM data'!$A$47:$A$66,0),MATCH(Speed!$K28,'LTM data'!$D$46:$W$46,0))} -> 484.71992 | W28: {=INDEX('LTM data'!$D$47:$W$66,MATCH(Speed!$H28&Speed!W$20,'LTM data'!$C$47:$C$66&'LTM data'!$A$47:$A$66,0),MATCH((Speed!$K28&" DKE"),'LTM data'!$D$46:$W$46,0))} -> 289.92242 | X28: =V28-W28 -> 194.7975 | Y28: {=INDEX('LTM data'!$D$47:$W$66,MATCH(Speed!$H28&Speed!Y$20,'LTM data'!$C$47:$C$66&'LTM data'!$A$47:$A$66,0),MATCH(Speed!$K28,'LTM data'!$D$46:$W$46,0))} -> 445.30183 | Z28: {=INDEX('LTM data'!$D$47:$W$66,MATCH(Speed!$H28&Speed!Z$20,'LTM data'!$C$47:$C$66&'LTM data'!$A$47:$A$66,0),MATCH((Speed!$K28&" DKE"),'LTM data'!$D$46:$W$46,0))} -> 266.34553 | AA28: =Y28-Z28 -> 178.9563 | AB28: =M28*$F28 -> 10.284402 | AC28: =$E28*N28 -> 6.1513433 | AD28: =$F28*O28 -> 4.1330583 | AE28: =P28*$F28 -> 11.138945 | AF28: =$E28*Q28 -> 6.6624659 | AG28: =$F28*R28 -> 4.4764792 | AH28: =S28*$F28 -> 11.447744 | AI28: =$E28*T28 -> 6.8471657 | AJ28: =$F28*U28 -> 4.6005781 | AK28: =V28*$F28 -> 10.2368 | AL28: =$E28*W28 -> 6.1228718 | AM28: =$F28*X28 -> 4.1139285 | AN28: =Y28*$F28 -> 9.4043297 | AO28: =$E28*Z28 -> 5.6249515 | AP28: =$F28*AA28 -> 3.7793782
C29: FLO_FUNC | D29: 2010 | E29: =1/$S$6 -> 0.015404284 | F29: =1/$S$6 -> 0.015404284 | G29: TPBU* | H29: TPL | I29: TIMEBL | K29: Public bus | M29: {=INDEX('LTM data'!$D$47:$W$66,MATCH(Speed!$H29&Speed!M$20,'LTM data'!$C$47:$C$66&'LTM data'!$A$47:$A$66,0),MATCH(Speed!$K29,'LTM data'!$D$46:$W$46,0))} -> 278.55243 | N29: {=INDEX('LTM data'!$D$47:$W$66,MATCH(Speed!$H29&Speed!N$20,'LTM data'!$C$47:$C$66&'LTM data'!$A$47:$A$66,0),MATCH((Speed!$K29&" DKE"),'LTM data'!$D$46:$W$46,0))} -> 166.60878 | O29: =M29-N29 -> 111.94365 | P29: {=INDEX('LTM data'!$D$47:$W$66,MATCH(Speed!$H29&Speed!P$20,'LTM data'!$C$47:$C$66&'LTM data'!$A$47:$A$66,0),MATCH(Speed!$K29,'LTM data'!$D$46:$W$46,0))} -> 301.69769 | Q29: {=INDEX('LTM data'!$D$47:$W$66,MATCH(Speed!$H29&Speed!Q$20,'LTM data'!$C$47:$C$66&'LTM data'!$A$47:$A$66,0),MATCH((Speed!$K29&" DKE"),'LTM data'!$D$46:$W$46,0))} -> 180.45251 | R29: =P29-Q29 -> 121.24518 | S29: {=INDEX('LTM data'!$D$47:$W$66,MATCH(Speed!$H29&Speed!S$20,'LTM data'!$C$47:$C$66&'LTM data'!$A$47:$A$66,0),MATCH(Speed!$K29,'LTM data'!$D$46:$W$46,0))} -> 310.06149 | T29: {=INDEX('LTM data'!$D$47:$W$66,MATCH(Speed!$H29&Speed!T$20,'LTM data'!$C$47:$C$66&'LTM data'!$A$47:$A$66,0),MATCH((Speed!$K29&" DKE"),'LTM data'!$D$46:$W$46,0))} -> 185.45509 | U29: =S29-T29 -> 124.60639 | V29: {=INDEX('LTM data'!$D$47:$W$66,MATCH(Speed!$H29&Speed!V$20,'LTM data'!$C$47:$C$66&'LTM data'!$A$47:$A$66,0),MATCH(Speed!$K29,'LTM data'!$D$46:$W$46,0))} -> 277.26315 | W29: {=INDEX('LTM data'!$D$47:$W$66,MATCH(Speed!$H29&Speed!W$20,'LTM data'!$C$47:$C$66&'LTM data'!$A$47:$A$66,0),MATCH((Speed!$K29&" DKE"),'LTM data'!$D$46:$W$46,0))} -> 165.83763 | X29: =V29-W29 -> 111.42552 | Y29: {=INDEX('LTM data'!$D$47:$W$66,MATCH(Speed!$H29&Speed!Y$20,'LTM data'!$C$47:$C$66&'LTM data'!$A$47:$A$66,0),MATCH(Speed!$K29,'LTM data'!$D$46:$W$46,0))} -> 254.71573 | Z29: {=INDEX('LTM data'!$D$47:$W$66,MATCH(Speed!$H29&Speed!Z$20,'LTM data'!$C$47:$C$66&'LTM data'!$A$47:$A$66,0),MATCH((Speed!$K29&" DKE"),'LTM data'!$D$46:$W$46,0))} -> 152.35149 | AA29: =Y29-Z29 -> 102.36424 | AB29: =M29*$F29 -> 4.2909005 | AC29: =$E29*N29 -> 2.5664889 | AD29: =$F29*O29 -> 1.7244117 | AE29: =P29*$F29 -> 4.6474367 | AF29: =$E29*Q29 -> 2.7797416 | AG29: =$F29*R29 -> 1.8676952 | AH29: =S29*$F29 -> 4.776275 | AI29: =$E29*T29 -> 2.8568028 | AJ29: =$F29*U29 -> 1.9194722 | AK29: =V29*$F29 -> 4.2710401 | AL29: =$E29*W29 -> 2.5546099 | AM29: =$F29*X29 -> 1.7164303 | AN29: =Y29*$F29 -> 3.9237133 | AO29: =$E29*Z29 -> 2.3468655 | AP29: =$F29*AA29 -> 1.5768478
C30: FLO_FUNC | D30: 2010 | E30: =1/$Q$8 -> 0.016436286 | F30: =1/$Q$8 -> 0.016436286 | G30: TPRO* | H30: TPS | I30: TIMETS | K30: Train | M30: {=INDEX('LTM data'!$D$47:$W$66,MATCH(Speed!$H30&Speed!M$20,'LTM data'!$C$47:$C$66&'LTM data'!$A$47:$A$66,0),MATCH(Speed!$K30,'LTM data'!$D$46:$W$46,0))} -> 413.37799 | N30: {=INDEX('LTM data'!$D$47:$W$66,MATCH(Speed!$H30&Speed!N$20,'LTM data'!$C$47:$C$66&'LTM data'!$A$47:$A$66,0),MATCH((Speed!$K30&" DKE"),'LTM data'!$D$46:$W$46,0))} -> 249.14816 | O30: =M30-N30 -> 164.22983 | P30: {=INDEX('LTM data'!$D$47:$W$66,MATCH(Speed!$H30&Speed!P$20,'LTM data'!$C$47:$C$66&'LTM data'!$A$47:$A$66,0),MATCH(Speed!$K30,'LTM data'!$D$46:$W$46,0))} -> 527.42105 | Q30: {=INDEX('LTM data'!$D$47:$W$66,MATCH(Speed!$H30&Speed!Q$20,'LTM data'!$C$47:$C$66&'LTM data'!$A$47:$A$66,0),MATCH((Speed!$K30&" DKE"),'LTM data'!$D$46:$W$46,0))} -> 317.88336 | R30: =P30-Q30 -> 209.53769 | S30: {=INDEX('LTM data'!$D$47:$W$66,MATCH(Speed!$H30&Speed!S$20,'LTM data'!$C$47:$C$66&'LTM data'!$A$47:$A$66,0),MATCH(Speed!$K30,'LTM data'!$D$46:$W$46,0))} -> 550.24187 | T30: {=INDEX('LTM data'!$D$47:$W$66,MATCH(Speed!$H30&Speed!T$20,'LTM data'!$C$47:$C$66&'LTM data'!$A$47:$A$66,0),MATCH((Speed!$K30&" DKE"),'LTM data'!$D$46:$W$46,0))} -> 331.63776 | U30: =S30-T30 -> 218.60411 | V30: {=INDEX('LTM data'!$D$47:$W$66,MATCH(Speed!$H30&Speed!V$20,'LTM data'!$C$47:$C$66&'LTM data'!$A$47:$A$66,0),MATCH(Speed!$K30,'LTM data'!$D$46:$W$46,0))} -> 633.99109 | W30: {=INDEX('LTM data'!$D$47:$W$66,MATCH(Speed!$H30&Speed!W$20,'LTM data'!$C$47:$C$66&'LTM data'!$A$47:$A$66,0),MATCH((Speed!$K30&" DKE"),'LTM data'!$D$46:$W$46,0))} -> 382.11448 | X30: =V30-W30 -> 251.87661 | Y30: {=INDEX('LTM data'!$D$47:$W$66,MATCH(Speed!$H30&Speed!Y$20,'LTM data'!$C$47:$C$66&'LTM data'!$A$47:$A$66,0),MATCH(Speed!$K30,'LTM data'!$D$46:$W$46,0))} -> 702.4235 | Z30: {=INDEX('LTM data'!$D$47:$W$66,MATCH(Speed!$H30&Speed!Z$20,'LTM data'!$C$47:$C$66&'LTM data'!$A$47:$A$66,0),MATCH((Speed!$K30&" DKE"),'LTM data'!$D$46:$W$46,0))} -> 423.35956 | AA30: =Y30-Z30 -> 279.06394 | AB30: =M30*$F30 -> 6.7943989 | AC30: =$E30*N30 -> 4.0950705 | AD30: =$F30*O30 -> 2.6993285 | AE30: =P30*$F30 -> 8.6688433 | AF30: =$E30*Q30 -> 5.2248219 | AG30: =$F30*R30 -> 3.4440214 | AH30: =S30*$F30 -> 9.0439327 | AI30: =$E30*T30 -> 5.450893 | AJ30: =$F30*U30 -> 3.5930397 | AK30: =V30*$F30 -> 10.420459 | AL30: =$E30*W30 -> 6.2805429 | AM30: =$F30*X30 -> 4.1399161 | AN30: =Y30*$F30 -> 11.545234 | AO30: =$E30*Z30 -> 6.9584588 | AP30: =$F30*AA30 -> 4.5867747
C31: FLO_FUNC | D31: 2010 | E31: =1/$R$8 -> 0.014120402 | F31: =1/$R$8 -> 0.014120402 | G31: TPRO* | H31: TPM | I31: TIMETM | K31: Train | M31: {=INDEX('LTM data'!$D$47:$W$66,MATCH(Speed!$H31&Speed!M$20,'LTM data'!$C$47:$C$66&'LTM data'!$A$47:$A$66,0),MATCH(Speed!$K31,'LTM data'!$D$46:$W$46,0))} -> 923.02188 | N31: {=INDEX('LTM data'!$D$47:$W$66,MATCH(Speed!$H31&Speed!N$20,'LTM data'!$C$47:$C$66&'LTM data'!$A$47:$A$66,0),MATCH((Speed!$K31&" DKE"),'LTM data'!$D$46:$W$46,0))} -> 556.317 | O31: =M31-N31 -> 366.70488 | P31: {=INDEX('LTM data'!$D$47:$W$66,MATCH(Speed!$H31&Speed!P$20,'LTM data'!$C$47:$C$66&'LTM data'!$A$47:$A$66,0),MATCH(Speed!$K31,'LTM data'!$D$46:$W$46,0))} -> 1177.6659 | Q31: {=INDEX('LTM data'!$D$47:$W$66,MATCH(Speed!$H31&Speed!Q$20,'LTM data'!$C$47:$C$66&'LTM data'!$A$47:$A$66,0),MATCH((Speed!$K31&" DKE"),'LTM data'!$D$46:$W$46,0))} -> 709.79419 | R31: =P31-Q31 -> 467.87172 | S31: {=INDEX('LTM data'!$D$47:$W$66,MATCH(Speed!$H31&Speed!S$20,'LTM data'!$C$47:$C$66&'LTM data'!$A$47:$A$66,0),MATCH(Speed!$K31,'LTM data'!$D$46:$W$46,0))} -> 1228.622 | T31: {=INDEX('LTM data'!$D$47:$W$66,MATCH(Speed!$H31&Speed!T$20,'LTM data'!$C$47:$C$66&'LTM data'!$A$47:$A$66,0),MATCH((Speed!$K31&" DKE"),'LTM data'!$D$46:$W$46,0))} -> 740.50605 | U31: =S31-T31 -> 488.11591 | V31: {=INDEX('LTM data'!$D$47:$W$66,MATCH(Speed!$H31&Speed!V$20,'LTM data'!$C$47:$C$66&'LTM data'!$A$47:$A$66,0),MATCH(Speed!$K31,'LTM data'!$D$46:$W$46,0))} -> 1415.6236 | W31: {=INDEX('LTM data'!$D$47:$W$66,MATCH(Speed!$H31&Speed!W$20,'LTM data'!$C$47:$C$66&'LTM data'!$A$47:$A$66,0),MATCH((Speed!$K31&" DKE"),'LTM data'!$D$46:$W$46,0))} -> 853.21432 | X31: =V31-W31 -> 562.40929 | Y31: {=INDEX('LTM data'!$D$47:$W$66,MATCH(Speed!$H31&Speed!Y$20,'LTM data'!$C$47:$C$66&'LTM data'!$A$47:$A$66,0),MATCH(Speed!$K31,'LTM data'!$D$46:$W$46,0))} -> 1568.4247 | Z31: {=INDEX('LTM data'!$D$47:$W$66,MATCH(Speed!$H31&Speed!Z$20,'LTM data'!$C$47:$C$66&'LTM data'!$A$47:$A$66,0),MATCH((Speed!$K31&" DKE"),'LTM data'!$D$46:$W$46,0))} -> 945.30948 | AA31: =Y31-Z31 -> 623.11523 | AB31: =M31*$F31 -> 13.03344 | AC31: =$E31*N31 -> 7.8554195 | AD31: =$F31*O31 -> 5.1780201 | AE31: =P31*$F31 -> 16.629116 | AF31: =$E31*Q31 -> 10.022579 | AG31: =$F31*R31 -> 6.6065365 | AH31: =S31*$F31 -> 17.348635 | AI31: =$E31*T31 -> 10.456243 | AJ31: =$F31*U31 -> 6.8923926 | AK31: =V31*$F31 -> 19.989174 | AL31: =$E31*W31 -> 12.047729 | AM31: =$F31*X31 -> 7.9414451 | AN31: =Y31*$F31 -> 22.146787 | AO31: =$E31*Z31 -> 13.348149 | AP31: =$F31*AA31 -> 8.7986372
C32: FLO_FUNC | D32: 2010 | E32: =1/$S$8 -> 0.010949578 | F32: =1/$S$8 -> 0.010949578 | G32: TPRO* | H32: TPL | I32: TIMETL | K32: Train | M32: {=INDEX('LTM data'!$D$47:$W$66,MATCH(Speed!$H32&Speed!M$20,'LTM data'!$C$47:$C$66&'LTM data'!$A$47:$A$66,0),MATCH(Speed!$K32,'LTM data'!$D$46:$W$46,0))} -> 3210.9002 | N32: {=INDEX('LTM data'!$D$47:$W$66,MATCH(Speed!$H32&Speed!N$20,'LTM data'!$C$47:$C$66&'LTM data'!$A$47:$A$66,0),MATCH((Speed!$K32&" DKE"),'LTM data'!$D$46:$W$46,0))} -> 1935.2503 | O32: =M32-N32 -> 1275.6499 | P32: {=INDEX('LTM data'!$D$47:$W$66,MATCH(Speed!$H32&Speed!P$20,'LTM data'!$C$47:$C$66&'LTM data'!$A$47:$A$66,0),MATCH(Speed!$K32,'LTM data'!$D$46:$W$46,0))} -> 4096.726 | Q32: {=INDEX('LTM data'!$D$47:$W$66,MATCH(Speed!$H32&Speed!Q$20,'LTM data'!$C$47:$C$66&'LTM data'!$A$47:$A$66,0),MATCH((Speed!$K32&" DKE"),'LTM data'!$D$46:$W$46,0))} -> 2469.1487 | R32: =P32-Q32 -> 1627.5772 | S32: {=INDEX('LTM data'!$D$47:$W$66,MATCH(Speed!$H32&Speed!S$20,'LTM data'!$C$47:$C$66&'LTM data'!$A$47:$A$66,0),MATCH(Speed!$K32,'LTM data'!$D$46:$W$46,0))} -> 4273.9859 | T32: {=INDEX('LTM data'!$D$47:$W$66,MATCH(Speed!$H32&Speed!T$20,'LTM data'!$C$47:$C$66&'LTM data'!$A$47:$A$66,0),MATCH((Speed!$K32&" DKE"),'LTM data'!$D$46:$W$46,0))} -> 2575.9855 | U32: =S32-T32 -> 1698.0003 | V32: {=INDEX('LTM data'!$D$47:$W$66,MATCH(Speed!$H32&Speed!V$20,'LTM data'!$C$47:$C$66&'LTM data'!$A$47:$A$66,0),MATCH(Speed!$K32,'LTM data'!$D$46:$W$46,0))} -> 4924.5053 | W32: {=INDEX('LTM data'!$D$47:$W$66,MATCH(Speed!$H32&Speed!W$20,'LTM data'!$C$47:$C$66&'LTM data'!$A$47:$A$66,0),MATCH((Speed!$K32&" DKE"),'LTM data'!$D$46:$W$46,0))} -> 2968.0618 | X32: =V32-W32 -> 1956.4434 | Y32: {=INDEX('LTM data'!$D$47:$W$66,MATCH(Speed!$H32&Speed!Y$20,'LTM data'!$C$47:$C$66&'LTM data'!$A$47:$A$66,0),MATCH(Speed!$K32,'LTM data'!$D$46:$W$46,0))} -> 5456.0518 | Z32: {=INDEX('LTM data'!$D$47:$W$66,MATCH(Speed!$H32&Speed!Z$20,'LTM data'!$C$47:$C$66&'LTM data'!$A$47:$A$66,0),MATCH((Speed!$K32&" DKE"),'LTM data'!$D$46:$W$46,0))} -> 3288.4317 | AA32: =Y32-Z32 -> 2167.6201 | AB32: =M32*$F32 -> 35.158003 | AC32: =$E32*N32 -> 21.190175 | AD32: =$F32*O32 -> 13.967828 | AE32: =P32*$F32 -> 44.857422 | AF32: =$E32*Q32 -> 27.036137 | AG32: =$F32*R32 -> 17.821284 | AH32: =S32*$F32 -> 46.798343 | AI32: =$E32*T32 -> 28.205955 | AJ32: =$F32*U32 -> 18.592388 | AK32: =V32*$F32 -> 53.921256 | AL32: =$E32*W32 -> 32.499026 | AM32: =$F32*X32 -> 21.422231 | AN32: =Y32*$F32 -> 59.741466 | AO32: =$E32*Z32 -> 36.00694 | AP32: =$F32*AA32 -> 23.734526
